Date              = Thu May  5 18:35:17 EDT 2022
Hostname          = node1208
Working Directory = /home/kimele03/uvvisml/uvvisml/models/log_lifetime_checkpoints/random

/home/kimele03/.conda/envs/uvvisml/lib/python3.7/site-packages/numpy/core/fromnumeric.py:3441: RuntimeWarning: Mean of empty slice.
  out=out, **kwargs)
/home/kimele03/.conda/envs/uvvisml/lib/python3.7/site-packages/numpy/core/_methods.py:189: RuntimeWarning: invalid value encountered in double_scalars
  ret = ret.dtype.type(ret / rcount)
Created experiment: https://app.sigopt.com/experiment/507325
Starting observation 0
Starting observation 1
Starting observation 2
Starting observation 3
Starting observation 4
Starting observation 5
Starting observation 6
Starting observation 7
Starting observation 8
Starting observation 9
Starting observation 10
Starting observation 11
Starting observation 12
Starting observation 13
Starting observation 14
Starting observation 15
Starting observation 16
Starting observation 17
Starting observation 18
Starting observation 19
Starting observation 20
Starting observation 21
Starting observation 22
Starting observation 23
Starting observation 24
Starting observation 25
Starting observation 26
Starting observation 27
Starting observation 28
Starting observation 29
Starting observation 30
Starting observation 31
Starting observation 32
Starting observation 33
Starting observation 34
Starting observation 35
Starting observation 36
Starting observation 37
Starting observation 38
Starting observation 39
Starting observation 40
Traceback (most recent call last):
  File "/home/kimele03/.conda/envs/uvvisml/lib/python3.7/site-packages/requests/models.py", line 473, in prepare_body
    body = complexjson.dumps(json, allow_nan=False)
  File "/home/kimele03/.conda/envs/uvvisml/lib/python3.7/json/__init__.py", line 238, in dumps
    **kw).encode(obj)
  File "/home/kimele03/.conda/envs/uvvisml/lib/python3.7/json/encoder.py", line 199, in encode
    chunks = self.iterencode(o, _one_shot=True)
  File "/home/kimele03/.conda/envs/uvvisml/lib/python3.7/json/encoder.py", line 257, in iterencode
    return _iterencode(o, 0)
ValueError: Out of range float values are not JSON compliant

During handling of the above exception, another exception occurred:

Traceback (most recent call last):
  File "/home/kimele03/.conda/envs/uvvisml/lib/python3.7/site-packages/sigopt/requestor.py", line 52, in request
    timeout=self.timeout,
  File "/home/kimele03/.conda/envs/uvvisml/lib/python3.7/site-packages/requests/api.py", line 61, in request
    return session.request(method=method, url=url, **kwargs)
  File "/home/kimele03/.conda/envs/uvvisml/lib/python3.7/site-packages/requests/sessions.py", line 515, in request
    prep = self.prepare_request(req)
  File "/home/kimele03/.conda/envs/uvvisml/lib/python3.7/site-packages/requests/sessions.py", line 453, in prepare_request
    hooks=merge_hooks(request.hooks, self.hooks),
  File "/home/kimele03/.conda/envs/uvvisml/lib/python3.7/site-packages/requests/models.py", line 321, in prepare
    self.prepare_body(data, files, json)
  File "/home/kimele03/.conda/envs/uvvisml/lib/python3.7/site-packages/requests/models.py", line 475, in prepare_body
    raise InvalidJSONError(ve, request=self)
requests.exceptions.InvalidJSONError: Out of range float values are not JSON compliant

During handling of the above exception, another exception occurred:

Traceback (most recent call last):
  File "../../chemprop_sigopt_engaging.py", line 158, in <module>
    main()
  File "../../chemprop_sigopt_engaging.py", line 140, in main
    value=value,
  File "/home/kimele03/.conda/envs/uvvisml/lib/python3.7/site-packages/sigopt/endpoint.py", line 24, in __call__
    return self.call_with_params(kwargs)
  File "/home/kimele03/.conda/envs/uvvisml/lib/python3.7/site-packages/sigopt/endpoint.py", line 17, in call_with_params
    raw_response = conn._request(self._endpoint._method, url, params)
  File "/home/kimele03/.conda/envs/uvvisml/lib/python3.7/site-packages/sigopt/interface.py", line 215, in _request
    params=params,
  File "/home/kimele03/.conda/envs/uvvisml/lib/python3.7/site-packages/sigopt/requestor.py", line 61, in request
    raise ConnectionException('\n'.join(message))
sigopt.exception.ConnectionException: ConnectionException: An error occurred connecting to SigOpt.
Contact support@sigopt.com for assistance.

Out of range float values are not JSON compliant
